<?xml version="1.0"?>

<robot name="arms">

    <link name="world"/>

    <!-- base_link. -->
    <link name="base_link">
        <visual>
            <geometry>
                <cylinder length="0.05" radius="0.2"/>
            </geometry>
            <material name="Black">
                <color rgba="0 0 0 1"/>
            </material>
            <origin rpy="0 0 0" xyz="0 0 0.025"/>
        </visual>

        <collision>
            <geometry>
                <cylinder length="0.05" radius="0.2"/>
            </geometry>
            <origin rpy="0 0 0" xyz="0 0 0.025"/>
        </collision>

    </link>

    <joint name="joint_base" type="fixed">
        <parent link="world"/>
        <child link="base_link"/>
        <origin xyz="0.0 0.0 0.0" rpy="0.0 0.0 0.0"/>
    </joint>

    <link name="link_1">
        <visual>
            <geometry>
                <cylinder length="0.5" radius="0.08"/>
            </geometry>
            <material name="blue">
                <color rgba="0 0 0.8 1"/>
            </material>
            <origin rpy="0 0 0" xyz="0 0 0.25"/>
        </visual>

        <collision>
            <geometry>
                <cylinder length="0.5" radius="0.08"/>
            </geometry>
            <origin rpy="0 0 0" xyz="0 0 0.25"/>
        </collision>
    </link>
    
    <link name="link_2">

        <visual>
            <geometry>
                <cylinder length="0.1" radius="0.08"/>
            </geometry>
            <material name="Red">
                <color rgba="1 0 0 1"/>
            </material>
        </visual>

        <collision>
            <geometry>
                <cylinder length="0.1" radius="0.08"/>
            </geometry>
        </collision>

    </link>

    <link name="link_3">

        <visual>
            <geometry>
                <cylinder length="0.4" radius="0.05"/>
            </geometry>
            <material name="blue">
                <color rgba="0.5 0.5 0.5 1"/>
            </material>
            <!-- <origin rpy="0 0 0" xyz="0 0 0.2"/> -->
        </visual>

        <collision>
            <geometry>
                <cylinder length="0.4" radius="0.05"/>
            </geometry>
        </collision>
    </link>


    <joint name="fixed" type="fixed">
        <parent link="world"/>
        <child link="base_link"/>

    </joint>

    <joint name="joint_1" type="continuous">
        <axis xyz="0 0 1"/>
        <parent link="base_link"/>
        <child link="link_1"/>
        <origin rpy="0 0 0" xyz="0.0 0.0 0.05"/>
    </joint>

    <joint name="joint_2" type="continuous">
        <axis xyz="0 0 1"/>
        <parent link="link_1"/>
        <child link="link_2"/>
        <origin rpy="0 1.5708 0" xyz="0.0 -0.005 0.58"/>
    </joint>

    <joint name="joint_3" type="fixed">
        <parent link="link_2"/>
        <child link="link_3"/>
        <origin rpy="1.57 0 0" xyz="0.0 0.2 0 "/>
    </joint>

</robot>
